[2024-08-07T09:32:27.341+0000] {taskinstance.py:1159} INFO - Dependencies all met for dep_context=non-requeueable deps ti=<TaskInstance: batch_processing_pipeline.download_data scheduled__2024-07-09T00:00:00+00:00 [queued]>
[2024-08-07T09:32:27.351+0000] {taskinstance.py:1159} INFO - Dependencies all met for dep_context=requeueable deps ti=<TaskInstance: batch_processing_pipeline.download_data scheduled__2024-07-09T00:00:00+00:00 [queued]>
[2024-08-07T09:32:27.352+0000] {taskinstance.py:1361} INFO - Starting attempt 2 of 2
[2024-08-07T09:32:27.368+0000] {taskinstance.py:1382} INFO - Executing <Task(PythonOperator): download_data> on 2024-07-09 00:00:00+00:00
[2024-08-07T09:32:27.373+0000] {standard_task_runner.py:57} INFO - Started process 2997 to run task
[2024-08-07T09:32:27.377+0000] {standard_task_runner.py:84} INFO - Running: ['***', 'tasks', 'run', 'batch_processing_pipeline', 'download_data', 'scheduled__2024-07-09T00:00:00+00:00', '--job-id', '1135', '--raw', '--subdir', 'DAGS_FOLDER/batch_processing_pipeline.py', '--cfg-path', '/tmp/tmplq5o96py']
[2024-08-07T09:32:27.380+0000] {standard_task_runner.py:85} INFO - Job 1135: Subtask download_data
[2024-08-07T09:32:27.436+0000] {task_command.py:416} INFO - Running <TaskInstance: batch_processing_pipeline.download_data scheduled__2024-07-09T00:00:00+00:00 [running]> on host 456c60cd3003
[2024-08-07T09:32:27.526+0000] {taskinstance.py:1662} INFO - Exporting env vars: AIRFLOW_CTX_DAG_OWNER='***' AIRFLOW_CTX_DAG_ID='batch_processing_pipeline' AIRFLOW_CTX_TASK_ID='download_data' AIRFLOW_CTX_EXECUTION_DATE='2024-07-09T00:00:00+00:00' AIRFLOW_CTX_TRY_NUMBER='2' AIRFLOW_CTX_DAG_RUN_ID='scheduled__2024-07-09T00:00:00+00:00'
[2024-08-07T09:32:27.529+0000] {taskinstance.py:1937} ERROR - Task failed with exception
Traceback (most recent call last):
  File "/home/airflow/.local/lib/python3.8/site-packages/airflow/operators/python.py", line 192, in execute
    return_value = self.execute_callable()
  File "/home/airflow/.local/lib/python3.8/site-packages/airflow/operators/python.py", line 209, in execute_callable
    return self.python_callable(*self.op_args, **self.op_kwargs)
  File "/opt/airflow/dags/batch_processing_pipeline.py", line 31, in run_direct_download
    from downloaders.direct_download import DirectDownloader
ModuleNotFoundError: No module named 'downloaders'
[2024-08-07T09:32:27.538+0000] {taskinstance.py:1400} INFO - Marking task as FAILED. dag_id=batch_processing_pipeline, task_id=download_data, execution_date=20240709T000000, start_date=20240807T093227, end_date=20240807T093227
[2024-08-07T09:32:27.553+0000] {standard_task_runner.py:104} ERROR - Failed to execute job 1135 for task download_data (No module named 'downloaders'; 2997)
[2024-08-07T09:32:27.589+0000] {local_task_job_runner.py:228} INFO - Task exited with return code 1
[2024-08-07T09:32:27.704+0000] {taskinstance.py:2778} INFO - 0 downstream tasks scheduled from follow-on schedule check
