[2024-08-07T02:36:47.802+0000] {taskinstance.py:1159} INFO - Dependencies all met for dep_context=non-requeueable deps ti=<TaskInstance: batch_processing_pipeline.download_data scheduled__2023-03-29T00:00:00+00:00 [queued]>
[2024-08-07T02:36:48.149+0000] {taskinstance.py:1159} INFO - Dependencies all met for dep_context=requeueable deps ti=<TaskInstance: batch_processing_pipeline.download_data scheduled__2023-03-29T00:00:00+00:00 [queued]>
[2024-08-07T02:36:48.151+0000] {taskinstance.py:1361} INFO - Starting attempt 1 of 2
[2024-08-07T02:36:49.016+0000] {taskinstance.py:1382} INFO - Executing <Task(PythonOperator): download_data> on 2023-03-29 00:00:00+00:00
[2024-08-07T02:36:49.119+0000] {standard_task_runner.py:57} INFO - Started process 188 to run task
[2024-08-07T02:36:49.159+0000] {standard_task_runner.py:84} INFO - Running: ['***', 'tasks', 'run', 'batch_processing_pipeline', 'download_data', 'scheduled__2023-03-29T00:00:00+00:00', '--job-id', '177', '--raw', '--subdir', 'DAGS_FOLDER/batch_processing_pipeline.py', '--cfg-path', '/tmp/tmpf1qkekkj']
[2024-08-07T02:36:49.209+0000] {standard_task_runner.py:85} INFO - Job 177: Subtask download_data
[2024-08-07T02:36:50.031+0000] {task_command.py:416} INFO - Running <TaskInstance: batch_processing_pipeline.download_data scheduled__2023-03-29T00:00:00+00:00 [running]> on host a4830aac3f3e
[2024-08-07T02:36:51.222+0000] {taskinstance.py:1662} INFO - Exporting env vars: AIRFLOW_CTX_DAG_OWNER='***' AIRFLOW_CTX_DAG_ID='batch_processing_pipeline' AIRFLOW_CTX_TASK_ID='download_data' AIRFLOW_CTX_EXECUTION_DATE='2023-03-29T00:00:00+00:00' AIRFLOW_CTX_TRY_NUMBER='1' AIRFLOW_CTX_DAG_RUN_ID='scheduled__2023-03-29T00:00:00+00:00'
[2024-08-07T02:36:51.253+0000] {taskinstance.py:1937} ERROR - Task failed with exception
Traceback (most recent call last):
  File "/home/airflow/.local/lib/python3.8/site-packages/airflow/operators/python.py", line 192, in execute
    return_value = self.execute_callable()
  File "/home/airflow/.local/lib/python3.8/site-packages/airflow/operators/python.py", line 209, in execute_callable
    return self.python_callable(*self.op_args, **self.op_kwargs)
  File "/opt/airflow/dags/batch_processing_pipeline.py", line 31, in run_direct_download
    from downloaders.direct_download import DirectDownloader
ModuleNotFoundError: No module named 'downloaders'
[2024-08-07T02:36:51.390+0000] {taskinstance.py:1400} INFO - Marking task as UP_FOR_RETRY. dag_id=batch_processing_pipeline, task_id=download_data, execution_date=20230329T000000, start_date=20240807T023647, end_date=20240807T023651
[2024-08-07T02:36:51.545+0000] {standard_task_runner.py:104} ERROR - Failed to execute job 177 for task download_data (No module named 'downloaders'; 188)
[2024-08-07T02:36:51.698+0000] {local_task_job_runner.py:228} INFO - Task exited with return code 1
[2024-08-07T02:36:51.861+0000] {taskinstance.py:2778} INFO - 0 downstream tasks scheduled from follow-on schedule check
