[2024-08-07T07:00:58.517+0000] {taskinstance.py:1159} INFO - Dependencies all met for dep_context=non-requeueable deps ti=<TaskInstance: batch_processing_pipeline.download_data scheduled__2023-07-08T00:00:00+00:00 [queued]>
[2024-08-07T07:00:58.606+0000] {taskinstance.py:1159} INFO - Dependencies all met for dep_context=requeueable deps ti=<TaskInstance: batch_processing_pipeline.download_data scheduled__2023-07-08T00:00:00+00:00 [queued]>
[2024-08-07T07:00:58.611+0000] {taskinstance.py:1361} INFO - Starting attempt 1 of 2
[2024-08-07T07:00:58.784+0000] {taskinstance.py:1382} INFO - Executing <Task(PythonOperator): download_data> on 2023-07-08 00:00:00+00:00
[2024-08-07T07:00:58.798+0000] {standard_task_runner.py:57} INFO - Started process 718 to run task
[2024-08-07T07:00:58.854+0000] {standard_task_runner.py:84} INFO - Running: ['***', 'tasks', 'run', 'batch_processing_pipeline', 'download_data', 'scheduled__2023-07-08T00:00:00+00:00', '--job-id', '375', '--raw', '--subdir', 'DAGS_FOLDER/batch_processing_pipeline.py', '--cfg-path', '/tmp/tmpwv95m0sv']
[2024-08-07T07:00:58.934+0000] {standard_task_runner.py:85} INFO - Job 375: Subtask download_data
[2024-08-07T07:00:59.418+0000] {task_command.py:416} INFO - Running <TaskInstance: batch_processing_pipeline.download_data scheduled__2023-07-08T00:00:00+00:00 [running]> on host 00a9d3678067
[2024-08-07T07:01:00.293+0000] {taskinstance.py:1662} INFO - Exporting env vars: AIRFLOW_CTX_DAG_OWNER='***' AIRFLOW_CTX_DAG_ID='batch_processing_pipeline' AIRFLOW_CTX_TASK_ID='download_data' AIRFLOW_CTX_EXECUTION_DATE='2023-07-08T00:00:00+00:00' AIRFLOW_CTX_TRY_NUMBER='1' AIRFLOW_CTX_DAG_RUN_ID='scheduled__2023-07-08T00:00:00+00:00'
[2024-08-07T07:01:00.299+0000] {taskinstance.py:1937} ERROR - Task failed with exception
Traceback (most recent call last):
  File "/home/airflow/.local/lib/python3.8/site-packages/airflow/operators/python.py", line 192, in execute
    return_value = self.execute_callable()
  File "/home/airflow/.local/lib/python3.8/site-packages/airflow/operators/python.py", line 209, in execute_callable
    return self.python_callable(*self.op_args, **self.op_kwargs)
  File "/opt/airflow/dags/batch_processing_pipeline.py", line 31, in run_direct_download
    from downloaders.direct_download import DirectDownloader
ModuleNotFoundError: No module named 'downloaders'
[2024-08-07T07:01:00.342+0000] {taskinstance.py:1400} INFO - Marking task as UP_FOR_RETRY. dag_id=batch_processing_pipeline, task_id=download_data, execution_date=20230708T000000, start_date=20240807T070058, end_date=20240807T070100
[2024-08-07T07:01:00.391+0000] {standard_task_runner.py:104} ERROR - Failed to execute job 375 for task download_data (No module named 'downloaders'; 718)
[2024-08-07T07:01:00.427+0000] {local_task_job_runner.py:228} INFO - Task exited with return code 1
[2024-08-07T07:01:00.571+0000] {taskinstance.py:2778} INFO - 0 downstream tasks scheduled from follow-on schedule check
