[2024-08-07T02:01:37.072+0000] {taskinstance.py:1159} INFO - Dependencies all met for dep_context=non-requeueable deps ti=<TaskInstance: batch_processing_pipeline.download_data scheduled__2023-01-18T00:00:00+00:00 [queued]>
[2024-08-07T02:01:37.137+0000] {taskinstance.py:1159} INFO - Dependencies all met for dep_context=requeueable deps ti=<TaskInstance: batch_processing_pipeline.download_data scheduled__2023-01-18T00:00:00+00:00 [queued]>
[2024-08-07T02:01:37.138+0000] {taskinstance.py:1361} INFO - Starting attempt 1 of 2
[2024-08-07T02:01:37.227+0000] {taskinstance.py:1382} INFO - Executing <Task(PythonOperator): download_data> on 2023-01-18 00:00:00+00:00
[2024-08-07T02:01:37.252+0000] {standard_task_runner.py:57} INFO - Started process 454 to run task
[2024-08-07T02:01:37.262+0000] {standard_task_runner.py:84} INFO - Running: ['***', 'tasks', 'run', 'batch_processing_pipeline', 'download_data', 'scheduled__2023-01-18T00:00:00+00:00', '--job-id', '27', '--raw', '--subdir', 'DAGS_FOLDER/batch_processing_pipeline.py', '--cfg-path', '/tmp/tmp3zoucnna']
[2024-08-07T02:01:37.281+0000] {standard_task_runner.py:85} INFO - Job 27: Subtask download_data
[2024-08-07T02:01:37.513+0000] {task_command.py:416} INFO - Running <TaskInstance: batch_processing_pipeline.download_data scheduled__2023-01-18T00:00:00+00:00 [running]> on host 1c2aad4b9155
[2024-08-07T02:01:37.906+0000] {taskinstance.py:1662} INFO - Exporting env vars: AIRFLOW_CTX_DAG_OWNER='***' AIRFLOW_CTX_DAG_ID='batch_processing_pipeline' AIRFLOW_CTX_TASK_ID='download_data' AIRFLOW_CTX_EXECUTION_DATE='2023-01-18T00:00:00+00:00' AIRFLOW_CTX_TRY_NUMBER='1' AIRFLOW_CTX_DAG_RUN_ID='scheduled__2023-01-18T00:00:00+00:00'
[2024-08-07T02:01:37.915+0000] {taskinstance.py:1937} ERROR - Task failed with exception
Traceback (most recent call last):
  File "/home/airflow/.local/lib/python3.8/site-packages/airflow/operators/python.py", line 192, in execute
    return_value = self.execute_callable()
  File "/home/airflow/.local/lib/python3.8/site-packages/airflow/operators/python.py", line 209, in execute_callable
    return self.python_callable(*self.op_args, **self.op_kwargs)
  File "/opt/airflow/dags/batch_processing_pipeline.py", line 31, in run_direct_download
    from downloaders.direct_download import DirectDownloader
ModuleNotFoundError: No module named 'downloaders'
[2024-08-07T02:01:37.945+0000] {taskinstance.py:1400} INFO - Marking task as UP_FOR_RETRY. dag_id=batch_processing_pipeline, task_id=download_data, execution_date=20230118T000000, start_date=20240807T020137, end_date=20240807T020137
[2024-08-07T02:01:37.998+0000] {standard_task_runner.py:104} ERROR - Failed to execute job 27 for task download_data (No module named 'downloaders'; 454)
[2024-08-07T02:01:38.031+0000] {local_task_job_runner.py:228} INFO - Task exited with return code 1
[2024-08-07T02:01:38.133+0000] {taskinstance.py:2778} INFO - 0 downstream tasks scheduled from follow-on schedule check
