[2024-08-07T06:43:38.896+0000] {taskinstance.py:1159} INFO - Dependencies all met for dep_context=non-requeueable deps ti=<TaskInstance: batch_processing_pipeline.download_data scheduled__2023-05-22T00:00:00+00:00 [queued]>
[2024-08-07T06:43:38.948+0000] {taskinstance.py:1159} INFO - Dependencies all met for dep_context=requeueable deps ti=<TaskInstance: batch_processing_pipeline.download_data scheduled__2023-05-22T00:00:00+00:00 [queued]>
[2024-08-07T06:43:38.948+0000] {taskinstance.py:1361} INFO - Starting attempt 1 of 2
[2024-08-07T06:43:38.999+0000] {taskinstance.py:1382} INFO - Executing <Task(PythonOperator): download_data> on 2023-05-22 00:00:00+00:00
[2024-08-07T06:43:39.019+0000] {standard_task_runner.py:57} INFO - Started process 190 to run task
[2024-08-07T06:43:39.064+0000] {standard_task_runner.py:84} INFO - Running: ['***', 'tasks', 'run', 'batch_processing_pipeline', 'download_data', 'scheduled__2023-05-22T00:00:00+00:00', '--job-id', '280', '--raw', '--subdir', 'DAGS_FOLDER/batch_processing_pipeline.py', '--cfg-path', '/tmp/tmp2ggfb6rx']
[2024-08-07T06:43:39.099+0000] {standard_task_runner.py:85} INFO - Job 280: Subtask download_data
[2024-08-07T06:43:39.681+0000] {task_command.py:416} INFO - Running <TaskInstance: batch_processing_pipeline.download_data scheduled__2023-05-22T00:00:00+00:00 [running]> on host 00a9d3678067
[2024-08-07T06:43:40.351+0000] {taskinstance.py:1662} INFO - Exporting env vars: AIRFLOW_CTX_DAG_OWNER='***' AIRFLOW_CTX_DAG_ID='batch_processing_pipeline' AIRFLOW_CTX_TASK_ID='download_data' AIRFLOW_CTX_EXECUTION_DATE='2023-05-22T00:00:00+00:00' AIRFLOW_CTX_TRY_NUMBER='1' AIRFLOW_CTX_DAG_RUN_ID='scheduled__2023-05-22T00:00:00+00:00'
[2024-08-07T06:43:40.364+0000] {taskinstance.py:1937} ERROR - Task failed with exception
Traceback (most recent call last):
  File "/home/airflow/.local/lib/python3.8/site-packages/airflow/operators/python.py", line 192, in execute
    return_value = self.execute_callable()
  File "/home/airflow/.local/lib/python3.8/site-packages/airflow/operators/python.py", line 209, in execute_callable
    return self.python_callable(*self.op_args, **self.op_kwargs)
  File "/opt/airflow/dags/batch_processing_pipeline.py", line 31, in run_direct_download
    from downloaders.direct_download import DirectDownloader
ModuleNotFoundError: No module named 'downloaders'
[2024-08-07T06:43:40.386+0000] {taskinstance.py:1400} INFO - Marking task as UP_FOR_RETRY. dag_id=batch_processing_pipeline, task_id=download_data, execution_date=20230522T000000, start_date=20240807T064338, end_date=20240807T064340
[2024-08-07T06:43:40.437+0000] {standard_task_runner.py:104} ERROR - Failed to execute job 280 for task download_data (No module named 'downloaders'; 190)
[2024-08-07T06:43:40.476+0000] {local_task_job_runner.py:228} INFO - Task exited with return code 1
[2024-08-07T06:43:40.556+0000] {taskinstance.py:2778} INFO - 0 downstream tasks scheduled from follow-on schedule check
